Workbook

Sheet Сводная таблица
E1: Расценка на осмотры | F1: Периодичность осмотров | G1: Расценка на обслуживание | H1: периодичносьт обслуживания
A2: Рубеж | B2: Прибор приемно‑контрольный пожарный | C2: R3‑Рубеж‑2ОП | D2: 7 | E2: нет | G2: 22-2203-101-1/1 | H2: 12
A3: Рубеж | B3: Пульт дистанционного управления | C3: R3‑Рубеж‑ПДУ | D3: 1 | G3: 22-2203-90-1/1 | H3: 12
A4: Рубеж | B4: Блок индикации и управления | C4: R3‑Рубеж‑БИУ | D4: 1 | G4: 22-2203-90-1/1 | H4: 12
A5: Рубеж | B5: Источник вторичного электропитания резервированный | C5: ИВЭПР 12/2 RS‑R3 2х17 БР‑R3 | D5: 2 | E5: 22-2201-78-1/1 | F5: 10 | G5: 22-2203-91-1/1 | H5: 2
A6: — | B6: Аккумуляторная батарея | C6: АКБ 17 Ач | D6: 4 | E6: не обслуживается
A7: — | B7: Бокс резервного питания | C7: БР 12 2х40 | D7: 2 | E7: 22-2201-78-1/1 | F7: 10 | G7: 22-2203-91-1/1 | H7: 2
A8: — | B8: Аккумуляторная батарея | C8: АКБ 40 Ач | D8: 4 | E8: не обслуживается
A9: Рубеж | B9: Источник вторичного электропитания резервированный | C9: ИВЭПР 12/2 RS‑R3 2х12 БР‑R3 | D9: 8 | E9: 22-2201-78-1/1 | F9: 10 | G9: 22-2203-91-1/1 | H9: 2
A10: — | B10: Аккумуляторная батарея | C10: АКБ 12 Ач | D10: 16 | E10: не обслуживается
A11: Рубеж | B11: Извещатель пожарный дымовой адресно‑аналоговый | C11: ИП 212‑64‑R3 | D11: 1524 | G11: 22-2203-106-1/1 | H11: 1
A12: Рубеж | B12: Извещатель пожарный дымовой адресно‑аналоговый (за подвесным потолком) | C12: ИП 212‑64‑R3 | D12: 294 | G12: 22-2203-106-1/1 | H12: 1
A13: Рубеж | B13: Извещатель пожарный ручной электроконтактный адресный с встроенным изолятором короткого замыкания | C13: ИПР 513‑11ИКЗ‑A‑R3 | D13: 102 | E13: 1-2201-30-1/1 | F13: 1 | G13: 1-2203-32-1/1 | H13: 1
A14: Рубеж | B14: Извещатель пожарный тепловой адресно‑аналоговый | C14: ИП 101‑29‑PR‑R3 | D14: 20 | G14: 22-2203-102-2/1 | H14: 2
A15: Рубеж | B15: Извещатель пожарный дымовой линейный | C15: ИПДЛ‑264/1‑50‑R3 | D15: 25 | E15: 22-2201-82-1/1 | F15: 1 | G15: 22-2203-127-1/1 | H15: 1
A16: Рубеж | B16: Изолятор шлейфа | C16: ИЗ‑1‑R3 | D16: 169 | G16: 22-2203-92-1/1 | H16: 12
A17: Рубеж | B17: Адресный релейный модуль | C17: РМ‑1‑R3 | D17: 87 | G17: 22-2203-104-4/1 | H17: 1
A18: Рубеж | B18: Адресный релейный модуль с контролем целостности цепи | C18: РМ‑1К‑R3 | D18: 4 | G18: 22-2203-104-4/1 | H18: 1
A19: Рубеж | B19: Адресный релейный модуль | C19: РМ‑4‑R3 | D19: 40 | E19: 22-2201-81-1/1 | F19: 11 | G19: 22-2203-104-11/1 | H19: 1
A20: Рубеж | B20: Адресный релейный модуль с контролем целостности цепи | C20: РМ‑4К‑R3 | D20: 12 | E20: 22-2201-81-1/1 | F20: 11 | G20: 22-2203-104-11/1 | H20: 1
A21: Рубеж | B21: Адресная метка | C21: АМ‑1‑R3 | D21: 4 | G21: 22-2203-104-7/1 | H21: 1
A22: Рубеж | B22: Программатор адресных устройств | C22: ПКУ‑1‑R3 | D22: 1
A23: Рубеж | B23: Устройство коммутационное | C23: УК‑ВК/12 | D23: 10 | G23: 22-2203-105-1/1 | H23: 1
A24: Рубеж | B24: Блок сопряжения | C24: R3‑MC1 | D24: 1 | G24: 22-2203-104-3/1 | H24: 1
A25: — | B25: Объектовая станция | C25: РСПИ | D25: 1 | E25: 22-2203-119-1/1 | F25: 1 | G25: 22-2203-119-2/1 | H25: 1
A26: Рубеж | B26: АРМ «Рубеж» | C26: ЦПИУ РУБЕЖ‑АРМ‑R3 | D26: 1 | G26: 22-2203-113-2/1 | H26: 12
A27: Бастион | B27: Источник бесперебойного питания | C27: SKAT‑UPS 1500/900 | D27: 1 | E27: 22-2201-78-1/1 | F27: 1 | G27: 22-2203-91-1/1 | H27: 1
A28: — | B28: Блок питания | C28: VDBPU‑208 | D28: 14
A29: Рубеж | B29: Адресный релейный модуль | C29: РМ‑1‑R3 | D29: 14 | G29: 22-2203-104-4/1 | H29: 1
A30: Рубеж | B30: Извещатель пожарный дымовой адресно‑аналоговый | C30: ИП 212‑64‑R3 | D30: 5 | G30: 22-2203-106-1/1 | H30: 1
A31: Рубеж | B31: Извещатель пожарный ручной адресный | C31: ИПР 513‑11‑R3 | D31: 1 | E31: 1-2201-30-1/1 | F31: 1 | G31: 1-2203-32-1/1 | H31: 1
A32: Рубеж | B32: Адресный релейный модуль с контролем целостности цепи | C32: РМ‑4К‑R3 | D32: 2 | E32: 22-2201-81-1/1 | F32: 11 | G32: 22-2203-104-11/1 | H32: 1
A33: Рубеж | B33: Оповещатель звуковой адресный | C33: ОПОП 124‑R3 | D33: 2 | G33: 22-2203-101-3/1 | H33: 4
A34: Рубеж | B34: Адресный оповещатель охранно‑пожарный световой | C34: ОПОП1‑R3 | D34: 2 | E34: 22-2201-80-2/1 | F34: 12
A35: Рубеж | B35: Изолятор шлейфа | C35: ИЗ‑1‑R3 | D35: 5 | G35: 22-2203-92-1/1 | H35: 12
I36: 1013939.4
B37: СОУЭ
A38: LPA | B38: Стойка оповещения в сборе | C38: LPA‑DUO | D38: 1 | E38: 22-2203-118-1/1 | F38: 11 | G38: 22-2203-118-2/1 | H38: 1
A39: LPA | B39: Громкоговоритель | C39: LPA‑6W | D39: 80 | E39: 22-2201-80-4/1 | F39: 12
A40: LPA | B40: Громкоговоритель | C40: LPA‑10W | D40: 22 | E40: 22-2201-80-4/1 | F40: 12
...

Sheet Данные для расчета
A1: Вспомогательные данные для расчета сметы
A2: Накладные расходы, в % от ЗП | B2: 0.7
A3: Нормативная прибыль, в % от ЗП | B3: 0.1
A4: Накладные расходы, в % от затрат на эксплуатацию машин | B4: 0.78
A5: Нормативная прибыль прибыль в % от затрат на эксплуатацию машин | B5: 0.3
A7: НДС | B7: 0.22
A9: Расчет коэффициента для Татарстана
A10: Среднемесячная заработная плата январь-декабрь, г. Москва | B10: 180861.1 | C10: https://www.fedstat.ru/indicator/57824
A11: Среднемесячная заработная плата январь-декабрь, Республика Татарстан | B11: 90515 | C11: https://www.fedstat.ru/indicator/57824
A12: Коэффициент | B12: =ROUND(B10/B11,3) -> 1.998

Sheet АПС СН-2012 расчёт
B1: АПС и СОУЭ | E1: =AO51 -> 1707086.3 | O1: Расчет в сметных нормативах сборника СН-2012 | AC1: Расчет с учетом корректировки ЗТР в уровень РТ
A2: план | B2: Наименование оборудования | C2: Тип оборудования | D2: Производитель оборудования | E2: Наименование мероприятия | F2: Шифр расценки | G2: Наименование расценки | H2: периодичность операции | I2: обоснование периодичности | J2: количество операций в год | K2: количество оборудования | L2: выполнений в год | M2: ед. измер. (на какой объем оборудования рассчитана расценка) | N2: Всего ед. измер. | O2: Цена на единицу измерения: ЗП | P2: Цена на ед. мзмерения: ЭМ | Q2: в том числе оплата труда машинистов | R2: Цена на ед. измер.: МР | S2: Поправочный коэффициент | T2: Всего ЗП: | U2: Всего: ЭМ | V2: в том числе ЗПМ | W2: Всего МР: | X2: НР | Y2: НП | Z2: Итого в год (без НДС) | AA2: НДС | AB2: Итого в год (с НДС) | AC2: Цена на единицу измерения: ЗП | AD2: Цена на ед. мзмерения: ЭМ | AE2: в том числе оплата труда машинистов | AF2: Цена на ед. измер.: МР | AG2: Всего ЗП: | AH2: Всего: ЭМ | AI2: в том числе ЗПМ | AJ2: Всего МР: | AK2: НР | AL2: НП | AM2: Итого в год (без НДС) | AN2: НДС | AO2: Итого в год (с НДС) | AP2: Справочно: затраты труда человеко-часов (на ед. измерения) | AQ2: Справочно: затраты труда человеко-часов (Общее за год) | AS2: Обоснование расценки
A3: 1 | B3: Прибор приемно‑контрольный пожарный | C3: R3‑Рубеж‑2ОП | D3: Рубеж | E3: Технический осмотр приборов контроля и управления (ППКП/ПУ/ППКУП) | F3: 22-2201-84-1/1 | G3: Технический осмотр прибора приемно-контрольного охранно-пожарного | H3: раз в 1 мес. | I3: ПКМ | J3: 8 | K3: 7 | L3: =K3*J3 -> 56 | M3: 1 | N3: =L3/M3 -> 56 | O3: 51.86 | P3: 0 | Q3: 0 | R3: 0.15 | S3: 1 | T3: =O3*N3*S3 -> 2904.16 | U3: =P3*N3*S3 -> 0 | V3: =Q3*N3*S3 -> 0 | W3: =R3*N3 -> 8.4 | X3: =($T3*'Данные для расчета'!$B$2+'Данные для расчета'!$B$4*$V3) -> 2032.912 | Y3: =($T3*'Данные для расчета'!$B$3+'Данные для расчета'!$B$5*$V3) -> 290.416 | Z3: =T3+U3+W3+X3+Y3 -> 5235.888 | AA3: =ROUND(Z3*'Данные для расчета'!$B$7,2) -> 1151.9 | AB3: =Z3+AA3 -> 6387.788 | AC3: =O3/'[1]Данные для расчета'!$B$12 -> 25.955956 | AD3: =P3-Q3+AE3 -> 0 | AE3: =Q3/'[1]Данные для расчета'!$B$12 -> 0 | AF3: =R3 -> 0.15 | AG3: =AC3*$N3*$S3 -> 1453.5335 | AH3: =AD3*$N3*$S3 -> 0 | AI3: =AE3*$N3*$S3 -> 0 | AJ3: =AF3*$N3*$S3 -> 8.4 | AK3: =($AG3*'Данные для расчета'!$B$2+'Данные для расчета'!$B$4*$AI3) -> 1017.4735 | AL3: =($AG3*'Данные для расчета'!$B$3+'Данные для расчета'!$B$5*$AI3) -> 145.35335 | AM3: =AG3+AH3+AJ3+AK3+AL3 -> 2624.7604 | AN3: =ROUND(AM3*'Данные для расчета'!$B$7,2) -> 577.45 | AO3: =AM3+AN3 -> 3202.2104 | AP3: 0.08 | AQ3: =L3*AP3 -> 4.48
A4: 1 | B4: Прибор приемно‑контрольный пожарный | C4: R3‑Рубеж‑2ОП | D4: Рубеж | E4: Техническое обслуживание приборов контроля и управления (ППКП/ПУ/ППКУП) | F4: 22-2203-101-1/1 | G4: ТО и регулировка прибора приемно-контрольного охранно-пожарного (Образование) | H4: раз в 3 мес. | I4: ПКМ | J4: 4 | K4: 7 | L4: =K4*J4 -> 28 | M4: 1 | N4: =L4/M4 -> 28 | O4: 402.31 | P4: 0 | Q4: 0 | R4: 2.06 | S4: 1 | T4: =O4*N4*S4 -> 11264.68 | U4: =P4*N4*S4 -> 0 | V4: =Q4*N4*S4 -> 0 | W4: =R4*N4 -> 57.68 | X4: =($T4*'Данные для расчета'!$B$2+'Данные для расчета'!$B$4*$V4) -> 7885.276 | Y4: =($T4*'Данные для расчета'!$B$3+'Данные для расчета'!$B$5*$V4) -> 1126.468 | Z4: =T4+U4+W4+X4+Y4 -> 20334.104 | AA4: =ROUND(Z4*'Данные для расчета'!$B$7,2) -> 4473.5 | AB4: =Z4+AA4 -> 24807.604 | AC4: =O4/'[1]Данные для расчета'!$B$12 -> 201.35636 | AD4: =P4-Q4+AE4 -> 0 | AE4: =Q4/'[1]Данные для расчета'!$B$12 -> 0 | AF4: =R4 -> 2.06 | AG4: =AC4*$N4*$S4 -> 5637.978 | AH4: =AD4*$N4*$S4 -> 0 | AI4: =AE4*$N4*$S4 -> 0 | AJ4: =AF4*$N4*$S4 -> 57.68 | AK4: =($AG4*'Данные для расчета'!$B$2+'Данные для расчета'!$B$4*$AI4) -> 3946.5846 | AL4: =($AG4*'Данные для расчета'!$B$3+'Данные для расчета'!$B$5*$AI4) -> 563.7978 | AM4: =AG4+AH4+AJ4+AK4+AL4 -> 10206.04 | AN4: =ROUND(AM4*'Данные для расчета'!$B$7,2) -> 2245.33 | AO4: =AM4+AN4 -> 12451.37 | AP4: 0.54 | AQ4: =L4*AP4 -> 15.12
A5: 2 | B5: Пульт дистанционного управления | C5: R3‑Рубеж‑ПДУ | D5: Рубеж | E5: Технический осмотр устройств управления (пульт ОПС, клавиатура, пульт настенный) | F5: 22-2201-77-1/1 | G5: Технический осмотр пульта охранно-пожарной сигнализации (ОПП) | H5: раз в 1 мес. | I5: ПКМ | J5: 8 | K5: 1 | L5: =K5*J5 -> 8 | M5: 10 | N5: =L5/M5 -> 0.8 | O5: 1762.51 | P5: 0 | Q5: 0 | R5: 4.19 | S5: 1 | T5: =O5*N5*S5 -> 1410.008 | U5: =P5*N5*S5 -> 0 | V5: =Q5*N5*S5 -> 0 | W5: =R5*N5 -> 3.352 | X5: =($T5*'Данные для расчета'!$B$2+'Данные для расчета'!$B$4*$V5) -> 987.0056 | Y5: =($T5*'Данные для расчета'!$B$3+'Данные для расчета'!$B$5*$V5) -> 141.0008 | Z5: =T5+U5+W5+X5+Y5 -> 2541.3664 | AA5: =ROUND(Z5*'Данные для расчета'!$B$7,2) -> 559.1 | AB5: =Z5+AA5 -> 3100.4664 | AC5: =O5/'[1]Данные для расчета'!$B$12 -> 882.13714 | AD5: =P5-Q5+AE5 -> 0 | AE5: =Q5/'[1]Данные для расчета'!$B$12 -> 0 | AF5: =R5 -> 4.19 | AG5: =AC5*$N5*$S5 -> 705.70971 | AH5: =AD5*$N5*$S5 -> 0 | AI5: =AE5*$N5*$S5 -> 0 | AJ5: =AF5*$N5*$S5 -> 3.352 | AK5: =($AG5*'Данные для расчета'!$B$2+'Данные для расчета'!$B$4*$AI5) -> 493.9968 | AL5: =($AG5*'Данные для расчета'!$B$3+'Данные для расчета'!$B$5*$AI5) -> 70.570971 | AM5: =AG5+AH5+AJ5+AK5+AL5 -> 1273.6295 | AN5: =ROUND(AM5*'Данные для расчета'!$B$7,2) -> 280.2 | AO5: =AM5+AN5 -> 1553.8295 | AP5: 2.53 | AQ5: =L5*AP5 -> 20.24
A6: 2 | B6: Пульт дистанционного управления | C6: R3‑Рубеж‑ПДУ | D6: Рубеж | E6: Техническое обслуживание устройств управления (пульт ОПС, клавиатура, пульт настенный) | F6: 22-2203-90-1/1 | G6: Техническое обслуживание пульта охранно-пожарной сигнализации (ОПП) | H6: раз в 3 мес. | I6: ПКМ | J6: 4 | K6: 1 | L6: =K6*J6 -> 4 | M6: 10 | N6: =L6/M6 -> 0.4 | O6: 4458.52 | P6: 0 | Q6: 0 | R6: 41.89 | S6: 1 | T6: =O6*N6*S6 -> 1783.408 | U6: =P6*N6*S6 -> 0 | V6: =Q6*N6*S6 -> 0 | W6: =R6*N6 -> 16.756 | X6: =($T6*'Данные для расчета'!$B$2+'Данные для расчета'!$B$4*$V6) -> 1248.3856 | Y6: =($T6*'Данные для расчета'!$B$3+'Данные для расчета'!$B$5*$V6) -> 178.3408 | Z6: =T6+U6+W6+X6+Y6 -> 3226.8904 | AA6: =ROUND(Z6*'Данные для расчета'!$B$7,2) -> 709.92 | AB6: =Z6+AA6 -> 3936.8104 | AC6: =O6/'[1]Данные для расчета'!$B$12 -> 2231.4915 | AD6: =P6-Q6+AE6 -> 0 | AE6: =Q6/'[1]Данные для расчета'!$B$12 -> 0 | AF6: =R6 -> 41.89 | AG6: =AC6*$N6*$S6 -> 892.5966 | AH6: =AD6*$N6*$S6 -> 0 | AI6: =AE6*$N6*$S6 -> 0 | AJ6: =AF6*$N6*$S6 -> 16.756 | AK6: =($AG6*'Данные для расчета'!$B$2+'Данные для расчета'!$B$4*$AI6) -> 624.81762 | AL6: =($AG6*'Данные для расчета'!$B$3+'Данные для расчета'!$B$5*$AI6) -> 89.25966 | AM6: =AG6+AH6+AJ6+AK6+AL6 -> 1623.4299 | AN6: =ROUND(AM6*'Данные для расчета'!$B$7,2) -> 357.15 | AO6: =AM6+AN6 -> 1980.5799 | AP6: 6.4 | AQ6: =L6*AP6 -> 25.6
A7: 3 | B7: Блок индикации и управления | C7: R3-Рубеж-БИУ | D7: Рубеж | E7: Технический осмотр устройств управления (пульт ОПС, клавиатура, пульт настенный) | F7: 22-2201-77-1/1 | G7: Технический осмотр пульта охранно-пожарной сигнализации (ОПП) | H7: раз в 1 мес. | I7: ПКМ | J7: 8 | K7: 1 | L7: =K7*J7 -> 8 | M7: 10 | N7: =L7/M7 -> 0.8 | O7: 1762.51 | P7: 0 | Q7: 0 | R7: 4.19 | S7: 1 | T7: =O7*N7*S7 -> 1410.008 | U7: =P7*N7*S7 -> 0 | V7: =Q7*N7*S7 -> 0 | W7: =R7*N7 -> 3.352 | X7: =($T7*'Данные для расчета'!$B$2+'Данные для расчета'!$B$4*$V7) -> 987.0056 | Y7: =($T7*'Данные для расчета'!$B$3+'Данные для расчета'!$B$5*$V7) -> 141.0008 | Z7: =T7+U7+W7+X7+Y7 -> 2541.3664 | AA7: =ROUND(Z7*'Данные для расчета'!$B$7,2) -> 559.1 | AB7: =Z7+AA7 -> 3100.4664 | AC7: =O7/'[1]Данные для расчета'!$B$12 -> 882.13714 | AD7: =P7-Q7+AE7 -> 0 | AE7: =Q7/'[1]Данные для расчета'!$B$12 -> 0 | AF7: =R7 -> 4.19 | AG7: =AC7*$N7*$S7 -> 705.70971 | AH7: =AD7*$N7*$S7 -> 0 | AI7: =AE7*$N7*$S7 -> 0 | AJ7: =AF7*$N7*$S7 -> 3.352 | AK7: =($AG7*'Данные для расчета'!$B$2+'Данные для расчета'!$B$4*$AI7) -> 493.9968 | AL7: =($AG7*'Данные для расчета'!$B$3+'Данные для расчета'!$B$5*$AI7) -> 70.570971 | AM7: =AG7+AH7+AJ7+AK7+AL7 -> 1273.6295 | AN7: =ROUND(AM7*'Данные для расчета'!$B$7,2) -> 280.2 | AO7: =AM7+AN7 -> 1553.8295 | AP7: 2.53 | AQ7: =L7*AP7 -> 20.24
A8: 3 | B8: Блок индикации и управления | C8: R3-Рубеж-БИУ | D8: Рубеж | E8: Техническое обслуживание устройств управления (пульт ОПС, клавиатура, пульт настенный) | F8: 22-2203-90-1/1 | G8: Техническое обслуживание пульта охранно-пожарной сигнализации (ОПП) | H8: раз в 3 мес. | I8: ПКМ | J8: 4 | K8: 1 | L8: =K8*J8 -> 4 | M8: 10 | N8: =L8/M8 -> 0.4 | O8: 4458.52 | P8: 0 | Q8: 0 | R8: 41.89 | S8: 1 | T8: =O8*N8*S8 -> 1783.408 | U8: =P8*N8*S8 -> 0 | V8: =Q8*N8*S8 -> 0 | W8: =R8*N8 -> 16.756 | X8: =($T8*'Данные для расчета'!$B$2+'Данные для расчета'!$B$4*$V8) -> 1248.3856 | Y8: =($T8*'Данные для расчета'!$B$3+'Данные для расчета'!$B$5*$V8) -> 178.3408 | Z8: =T8+U8+W8+X8+Y8 -> 3226.8904 | AA8: =ROUND(Z8*'Данные для расчета'!$B$7,2) -> 709.92 | AB8: =Z8+AA8 -> 3936.8104 | AC8: =O8/'[1]Данные для расчета'!$B$12 -> 2231.4915 | AD8: =P8-Q8+AE8 -> 0 | AE8: =Q8/'[1]Данные для расчета'!$B$12 -> 0 | AF8: =R8 -> 41.89 | AG8: =AC8*$N8*$S8 -> 892.5966 | AH8: =AD8*$N8*$S8 -> 0 | AI8: =AE8*$N8*$S8 -> 0 | AJ8: =AF8*$N8*$S8 -> 16.756 | AK8: =($AG8*'Данные для расчета'!$B$2+'Данные для расчета'!$B$4*$AI8) -> 624.81762 | AL8: =($AG8*'Данные для расчета'!$B$3+'Данные для расчета'!$B$5*$AI8) -> 89.25966 | AM8: =AG8+AH8+AJ8+AK8+AL8 -> 1623.4299 | AN8: =ROUND(AM8*'Данные для расчета'!$B$7,2) -> 357.15 | AO8: =AM8+AN8 -> 1980.5799 | AP8: 6.4 | AQ8: =L8*AP8 -> 25.6
A9: 4 | B9: Источник вторичного электропитания резервированный | C9: ИВЭПР 12/2 RS-R3 2х17 БР-R3 | D9: Теко | E9: Проверка автономного питания, замена АКБ при несоответствии | F9: 22-2201-78-1/1 | G9: Технический осмотр источника вторичного электропитания ИВЭП 112-0,3-1 «Астра-БП1» | H9: раз в 1 мес. | I9: Паспорт | J9: 10 | K9: 2 | L9: =K9*J9 -> 20 | M9: 1 | N9: =L9/M9 -> 20 | O9: 62.7 | P9: 0 | Q9: 0 | R9: 3.38 | S9: 1 | T9: =O9*N9*S9 -> 1254 | U9: =P9*N9*S9 -> 0 | V9: =Q9*N9*S9 -> 0 | W9: =R9*N9 -> 67.6 | X9: =($T9*'Данные для расчета'!$B$2+'Данные для расчета'!$B$4*$V9) -> 877.8 | Y9: =($T9*'Данные для расчета'!$B$3+'Данные для расчета'!$B$5*$V9) -> 125.4 | Z9: =T9+U9+W9+X9+Y9 -> 2324.8 | AA9: =ROUND(Z9*'Данные для расчета'!$B$7,2) -> 511.46 | AB9: =Z9+AA9 -> 2836.26 | AC9: =O9/'[2]Данные для расчета'!$B$12 -> 31.381381 | AD9: =P9-Q9+AE9 -> 0 | AE9: =Q9/'[2]Данные для расчета'!$B$12 -> 0 | AF9: =R9 -> 3.38 | AG9: =AC9*$N9*$S9 -> 627.62763 | AH9: =AD9*$N9*$S9 -> 0 | AI9: =AE9*$N9*$S9 -> 0 | AJ9: =AF9*$N9 -> 67.6 | AK9: =($AG9*'Данные для расчета'!$B$2+'Данные для расчета'!$B$4*$AI9) -> 439.33934 | AL9: =($AG9*'Данные для расчета'!$B$3+'Данные для расчета'!$B$5*$AI9) -> 62.762763 | AM9: =AG9+AH9+AJ9+AK9+AL9 -> 1197.3297 | AN9: =ROUND(AM9*'Данные для расчета'!$B$7,2) -> 263.41 | AO9: =AM9+AN9 -> 1460.7397 | AP9: 0.09 | AQ9: =L9*AP9 -> 1.8
A10: 4 | B10: Источник вторичного электропитания резервированный | C10: ИВЭПР 12/2 RS-R3 2х17 БР-R3 | D10: Теко | E10: Технический осмотр блока питания / источника резервного питания | F10: 22-2203-91-1/1 | G10: Техническое обслуживание источника вторичного электропитания типа ИВЭП 112-0,3-1 "Астра-БП1 | H10: раз в 6 мес. | I10: Паспорт | J10: 2 | K10: 2 | L10: =K10*J10 -> 4 | M10: 1 | N10: =L10/M10 -> 4 | O10: 877.77 | P10: 0 | Q10: 0 | R10: 3.38 | S10: 1 | T10: =O10*N10*S10 -> 3511.08 | U10: =P10*N10*S10 -> 0 | V10: =Q10*N10*S10 -> 0 | W10: =R10*N10 -> 13.52 | X10: =($T10*'Данные для расчета'!$B$2+'Данные для расчета'!$B$4*$V10) -> 2457.756 | Y10: =($T10*'Данные для расчета'!$B$3+'Данные для расчета'!$B$5*$V10) -> 351.108 | Z10: =T10+U10+W10+X10+Y10 -> 6333.464 | AA10: =ROUND(Z10*'Данные для расчета'!$B$7,2) -> 1393.36 | AB10: =Z10+AA10 -> 7726.824 | AC10: =O10/'[2]Данные для расчета'!$B$12 -> 439.32432 | AD10: =P10-Q10+AE10 -> 0 | AE10: =Q10/'[2]Данные для расчета'!$B$12 -> 0 | AF10: =R10 -> 3.38 | AG10: =AC10*$N10*$S10 -> 1757.2973 | AH10: =AD10*$N10*$S10 -> 0 | AI10: =AE10*$N10*$S10 -> 0 | AJ10: =AF10*$N10 -> 13.52 | AK10: =($AG10*'Данные для расчета'!$B$2+'Данные для расчета'!$B$4*$AI10) -> 1230.1081 | AL10: =($AG10*'Данные для расчета'!$B$3+'Данные для расчета'!$B$5*$AI10) -> 175.72973 | AM10: =AG10+AH10+AJ10+AK10+AL10 -> 3176.6551 | AN10: =ROUND(AM10*'Данные для расчета'!$B$7,2) -> 698.86 | AO10: =AM10+AN10 -> 3875.5151 | AP10: 1.26 | AQ10: =L10*AP10 -> 5.04
A11: 6 | B11: Бокс резервного питания | C11: БР-R3 исп.2х40 | D11: Рубеж | E11: Ежемесячный осмотр, контроль функционирования 1 раз в 6 мес | F11: 22-2201-67-1/1 | G11: Технический осмотр блока питания типа БРП-12-01Л | H11: раз в 1 мес. | I11: Паспорт | J11: 10 | K11: 2 | L11: =K11*J11 -> 20 | M11: 1 | N11: =L11/M11 -> 20 | O11: 139.33 | P11: 0 | Q11: 0 | R11: 7.15 | S11: 1 | T11: =O11*N11*S11 -> 2786.6 | U11: =P11*N11*S11 -> 0 | V11: =Q11*N11*S11 -> 0 | W11: =R11*N11 -> 143 | X11: =($T11*'Данные для расчета'!$B$2+'Данные для расчета'!$B$4*$V11) -> 1950.62 | Y11: =($T11*'Данные для расчета'!$B$3+'Данные для расчета'!$B$5*$V11) -> 278.66 | Z11: =T11+U11+W11+X11+Y11 -> 5158.88 | AA11: =ROUND(Z11*'Данные для расчета'!$B$7,2) -> 1134.95 | AB11: =Z11+AA11 -> 6293.83 | AC11: =O11/'[2]Данные для расчета'!$B$12 -> 69.734735 | AD11: =P11-Q11+AE11 -> 0 | AE11: =Q11/'[2]Данные для расчета'!$B$12 -> 0 | AF11: =R11 -> 7.15 | AG11: =AC11*$N11*$S11 -> 1394.6947 | AH11: =AD11*$N11*$S11 -> 0 | AI11: =AE11*$N11*$S11 -> 0 | AJ11: =AF11*$N11 -> 143 | AK11: =($AG11*'Данные для расчета'!$B$2+'Данные для расчета'!$B$4*$AI11) -> 976.28629 | AL11: =($AG11*'Данные для расчета'!$B$3+'Данные для расчета'!$B$5*$AI11) -> 139.46947 | AM11: =AG11+AH11+AJ11+AK11+AL11 -> 2653.4505 | AN11: =ROUND(AM11*'Данные для расчета'!$B$7,2) -> 583.76 | AO11: =AM11+AN11 -> 3237.2105 | AP11: 0.2 | AQ11: =L11*AP11 -> 4
A12: 6 | B12: Бокс резервного питания | C12: БР-R3 исп.2х40 | D12: Рубеж | E12: Ежемесячный осмотр, контроль функционирования 1 раз в 6 мес | F12: 22-2203-78-1/1 | G12: Техническое обслуживание блока питания типа БРП-12-01Л | H12: раз в 6 мес. | I12: Паспорт | J12: 2 | K12: 2 | L12: =K12*J12 -> 4 | M12: 1 | N12: =L12/M12 -> 4 | O12: 501.59 | P12: 0 | Q12: 0 | R12: 3.85 | S12: 1 | T12: =O12*N12*S12 -> 2006.36 | U12: =P12*N12*S12 -> 0 | V12: =Q12*N12*S12 -> 0 | W12: =R12*N12 -> 15.4 | X12: =($T12*'Данные для расчета'!$B$2+'Данные для расчета'!$B$4*$V12) -> 1404.452 | Y12: =($T12*'Данные для расчета'!$B$3+'Данные для расчета'!$B$5*$V12) -> 200.636 | Z12: =T12+U12+W12+X12+Y12 -> 3626.848 | AA12: =ROUND(Z12*'Данные для расчета'!$B$7,2) -> 797.91 | AB12: =Z12+AA12 -> 4424.758 | AC12: =O12/'[2]Данные для расчета'!$B$12 -> 251.04605 | AD12: =P12-Q12+AE12 -> 0 | AE12: =Q12/'[2]Данные для расчета'!$B$12 -> 0 | AF12: =R12 -> 3.85 | AG12: =AC12*$N12*$S12 -> 1004.1842 | AH12: =AD12*$N12*$S12 -> 0 | AI12: =AE12*$N12*$S12 -> 0 | AJ12: =AF12*$N12 -> 15.4 | AK12: =($AG12*'Данные для расчета'!$B$2+'Данные для расчета'!$B$4*$AI12) -> 702.92893 | AL12: =($AG12*'Данные для расчета'!$B$3+'Данные для расчета'!$B$5*$AI12) -> 100.41842 | AM12: =AG12+AH12+AJ12+AK12+AL12 -> 1822.9315 | AN12: =ROUND(AM12*'Данные для расчета'!$B$7,2) -> 401.04 | AO12: =AM12+AN12 -> 2223.9715 | AP12: 0.72 | AQ12: =L12*AP12 -> 2.88
A13: 8 | B13: Источник вторичного электропитания резервированный | C13: ИВЭПР 12/2 RS-R3 2х12 БР-R3 | D13: Теко | E13: Проверка автономного питания, замена АКБ при несоответствии | F13: 22-2201-78-1/1 | G13: Технический осмотр источника вторичного электропитания ИВЭП 112-0,3-1 «Астра-БП1» | H13: раз в 1 мес. | I13: Паспорт | J13: 10 | K13: 8 | L13: =K13*J13 -> 80 | M13: 1 | N13: =L13/M13 -> 80 | O13: 62.7 | P13: 0 | Q13: 0 | R13: 3.38 | S13: 1 | T13: =O13*N13*S13 -> 5016 | U13: =P13*N13*S13 -> 0 | V13: =Q13*N13*S13 -> 0 | W13: =R13*N13 -> 270.4 | X13: =($T13*'Данные для расчета'!$B$2+'Данные для расчета'!$B$4*$V13) -> 3511.2 | Y13: =($T13*'Данные для расчета'!$B$3+'Данные для расчета'!$B$5*$V13) -> 501.6 | Z13: =T13+U13+W13+X13+Y13 -> 9299.2 | AA13: =ROUND(Z13*'Данные для расчета'!$B$7,2) -> 2045.82 | AB13: =Z13+AA13 -> 11345.02 | AC13: =O13/'[2]Данные для расчета'!$B$12 -> 31.381381 | AD13: =P13-Q13+AE13 -> 0 | AE13: =Q13/'[2]Данные для расчета'!$B$12 -> 0 | AF13: =R13 -> 3.38 | AG13: =AC13*$N13*$S13 -> 2510.5105 | AH13: =AD13*$N13*$S13 -> 0 | AI13: =AE13*$N13*$S13 -> 0 | AJ13: =AF13*$N13 -> 270.4 | AK13: =($AG13*'Данные для расчета'!$B$2+'Данные для расчета'!$B$4*$AI13) -> 1757.3574 | AL13: =($AG13*'Данные для расчета'!$B$3+'Данные для расчета'!$B$5*$AI13) -> 251.05105 | AM13: =AG13+AH13+AJ13+AK13+AL13 -> 4789.3189 | AN13: =ROUND(AM13*'Данные для расчета'!$B$7,2) -> 1053.65 | AO13: =AM13+AN13 -> 5842.9689 | AP13: 0.09 | AQ13: =L13*AP13 -> 7.2
A14: 8 | B14: Источник вторичного электропитания резервированный | C14: ИВЭПР 12/2 RS-R3 2х12 БР-R3 | D14: Теко | E14: Технический осмотр блока питания / источника резервного питания | F14: 22-2203-91-1/1 | G14: Техническое обслуживание источника вторичного электропитания типа ИВЭП 112-0,3-1 "Астра-БП1 | H14: раз в 6 мес. | I14: Паспорт | J14: 2 | K14: 8 | L14: =K14*J14 -> 16 | M14: 1 | N14: =L14/M14 -> 16 | O14: 877.77 | P14: 0 | Q14: 0 | R14: 3.38 | S14: 1 | T14: =O14*N14*S14 -> 14044.32 | U14: =P14*N14*S14 -> 0 | V14: =Q14*N14*S14 -> 0 | W14: =R14*N14 -> 54.08 | X14: =($T14*'Данные для расчета'!$B$2+'Данные для расчета'!$B$4*$V14) -> 9831.024 | Y14: =($T14*'Данные для расчета'!$B$3+'Данные для расчета'!$B$5*$V14) -> 1404.432 | Z14: =T14+U14+W14+X14+Y14 -> 25333.856 | AA14: =ROUND(Z14*'Данные для расчета'!$B$7,2) -> 5573.45 | AB14: =Z14+AA14 -> 30907.306 | AC14: =O14/'[2]Данные для расчета'!$B$12 -> 439.32432 | AD14: =P14-Q14+AE14 -> 0 | AE14: =Q14/'[2]Данные для расчета'!$B$12 -> 0 | AF14: =R14 -> 3.38 | AG14: =AC14*$N14*$S14 -> 7029.1892 | AH14: =AD14*$N14*$S14 -> 0 | AI14: =AE14*$N14*$S14 -> 0 | AJ14: =AF14*$N14 -> 54.08 | AK14: =($AG14*'Данные для расчета'!$B$2+'Данные для расчета'!$B$4*$AI14) -> 4920.4324 | AL14: =($AG14*'Данные для расчета'!$B$3+'Данные для расчета'!$B$5*$AI14) -> 702.91892 | AM14: =AG14+AH14+AJ14+AK14+AL14 -> 12706.621 | AN14: =ROUND(AM14*'Данные для расчета'!$B$7,2) -> 2795.46 | AO14: =AM14+AN14 -> 15502.081 | AP14: 1.26 | AQ14: =L14*AP14 -> 20.16
A15: 10, 11, 38 | B15: Извещатель пожарный дымовой адресно-аналоговый | C15: ИП 212-64-R3 W1.03 | E15: Осмотр извещателя | F15: 1-2201-35-1/1 | G15: Технический осмотр извещателя пожарного дымового аналогово-адресного "ДИП-34А" | H15: раз в 6 мес. | I15: Паспорт | J15: 1 | K15: =1818+5 -> 1823 | L15: =K15*J15 -> 1823 | M15: 1 | N15: =L15/M15 -> 1823 | O15: 52.15 | P15: 5.51 | Q15: 3.32 | R15: 0 | S15: 0.75 | T15: =O15*N15*S15 -> 71302.087 | U15: =P15*N15*S15 -> 7533.5475 | V15: =Q15*N15*S15 -> 4539.27 | W15: =R15*N15 -> 0 | X15: =($T15*'Данные для расчета'!$B$2+'Данные для расчета'!$B$4*$V15) -> 53452.092 | Y15: =($T15*'Данные для расчета'!$B$3+'Данные для расчета'!$B$5*$V15) -> 8491.9897 | Z15: =T15+U15+W15+X15+Y15 -> 140779.72 | AA15: =ROUND(Z15*'Данные для расчета'!$B$7,2) -> 30971.54 | AB15: =Z15+AA15 -> 171751.26 | AC15: =O15/'[2]Данные для расчета'!$B$12 -> 26.101101 | AD15: =P15-Q15+AE15 -> 3.8516617 | AE15: =Q15/'[2]Данные для расчета'!$B$12 -> 1.6616617 | AF15: =R15 -> 0 | AG15: =AC15*$N15*$S15 -> 35686.73 | AH15: =AD15*$N15*$S15 -> 5266.1844 | AI15: =AE15*$N15*$S15 -> 2271.9069 | AJ15: =AF15*$N15 -> 0 | AK15: =($AG15*'Данные для расчета'!$B$2+'Данные для расчета'!$B$4*$AI15) -> 26752.799 | AL15: =($AG15*'Данные для расчета'!$B$3+'Данные для расчета'!$B$5*$AI15) -> 4250.2451 | AM15: =AG15+AH15+AJ15+AK15+AL15 -> 71955.959 | AN15: =ROUND(AM15*'Данные для расчета'!$B$7,2) -> 15830.31 | AO15: =AM15+AN15 -> 87786.269 | AP15: 0.07 | AQ15: =L15*AP15 -> 127.61
A16: 10, 11, 39 | B16: Извещатель пожарный дымовой адресно-аналоговый | C16: ИП 212-64-R3 W1.03 | E16: Техническое обслуживание 1 | F16: 22-2203-106-1/1 | G16: ТО извещателя пожарного дымового оптико-электронного адресно-аналогового | H16: раз в год | I16: Паспорт | J16: 1 | K16: =1818+5 -> 1823 | L16: =K16*J16 -> 1823 | M16: 1 | N16: =L16/M16 -> 1823 | O16: 111.46 | P16: 0 | Q16: 0 | R16: 0.06 | S16: 1 | T16: =O16*N16*S16 -> 203191.58 | U16: =P16*N16*S16 -> 0 | V16: =Q16*N16*S16 -> 0 | W16: =R16*N16 -> 109.38 | X16: =($T16*'Данные для расчета'!$B$2+'Данные для расчета'!$B$4*$V16) -> 142234.11 | Y16: =($T16*'Данные для расчета'!$B$3+'Данные для расчета'!$B$5*$V16) -> 20319.158 | Z16: =T16+U16+W16+X16+Y16 -> 365854.22 | AA16: =ROUND(Z16*'Данные для расчета'!$B$7,2) -> 80487.93 | AB16: =Z16+AA16 -> 446342.15 | AC16: =O16/'[1]Данные для расчета'!$B$12 -> 55.785786 | AD16: =P16-Q16+AE16 -> 0 | AE16: =Q16/'[1]Данные для расчета'!$B$12 -> 0 | AF16: =R16 -> 0.06 | AG16: =AC16*$N16*$S16 -> 101697.49 | AH16: =AD16*$N16*$S16 -> 0 | AI16: =AE16*$N16*$S16 -> 0 | AJ16: =AF16*$N16*$S16 -> 109.38 | AK16: =($AG16*'Данные для расчета'!$B$2+'Данные для расчета'!$B$4*$AI16) -> 71188.241 | AL16: =($AG16*'Данные для расчета'!$B$3+'Данные для расчета'!$B$5*$AI16) -> 10169.749 | AM16: =AG16+AH16+AJ16+AK16+AL16 -> 183164.86 | AN16: =ROUND(AM16*'Данные для расчета'!$B$7,2) -> 40296.27 | AO16: =AM16+AN16 -> 223461.13 | AP16: 0.16 | AQ16: =L16*AP16 -> 291.68 | AS16: С целью поддержания исправности ИП в период эксплуатации необходимо проведение регламентных работ, с периодичностью, согласно ГОСТ Р 59638-2021, которые включают в себя внешний осмотр, с удалением пыли мягкой тканью и кисточкой, и контроль работоспособности. При появлении сообщения «Предварительная запыленность» или «Критическая запыленность» на приборе, на персональном компьютере с ПО «Firesec» и не реже одного раза в год необходимо продуть сжатым воздухом в течение одной минуты со всех сторон оптическую систему ИП через щелевые 2 отверстия в корпусе ИП, используя для этой цели пылесос либо иной компрессор с давлением (4 – 5) кг/см . Продувку ИП допускается производить как в условиях мастерской (лаборатории), так и по штатному месту установки. Продувку со снятием ИП следует производить согласно приложению Г. При сильном загрязнении допускается произвести неполную разборку ИП, согласно приложению Д. Если продувка проводилась со снятием ИП, то после его повторной установки необходимо выполнить действия, приведенные в 7.2. Не реже одного раза в год рекомендуется производить контроль работоспособности ИП в системе пожарной сигнализации со срабатыванием от кнопки ТЕСТ или оптического тестера
A17: 10, 11, 40 | B17: Извещатель пожарный дымовой адресно-аналоговый | C17: ИП 212-64-R3 W1.03 | E17: Техническое обслуживание 2 Контроль работоспособности извещателя | F17: 22-2203-106-2/1 | G17: Техническое обслуживание извещателя пожарного дымового оптико-электронного адресно-аналогового ИП 212-34А "ДИП-34А" - испытания извещателя | H17: раз в 1 год | I17: Паспорт | J17: 1 | K17: =1818+5 -> 1823 | L17: =K17*J17 -> 1823 | M17: 1 | N17: =L17/M17 -> 1823 | O17: 153.26 | P17: 0 | Q17: 0 | R17: 0 | S17: 1 | T17: =O17*N17*S17 -> 279392.98 | U17: =P17*N17*S17 -> 0 | V17: =Q17*N17*S17 -> 0 | W17: =R17*N17 -> 0 | X17: =($T17*'Данные для расчета'!$B$2+'Данные для расчета'!$B$4*$V17) -> 195575.09 | Y17: =($T17*'Данные для расчета'!$B$3+'Данные для расчета'!$B$5*$V17) -> 27939.298 | Z17: =T17+U17+W17+X17+Y17 -> 502907.36 | AA17: =ROUND(Z17*'Данные для расчета'!$B$7,2) -> 110639.62 | AB17: =Z17+AA17 -> 613546.98 | AC17: =O17/'[1]Данные для расчета'!$B$12 -> 76.706707 | AD17: =P17-Q17+AE17 -> 0 | AE17: =Q17/'[1]Данные для расчета'!$B$12 -> 0 | AF17: =R17 -> 0 | AG17: =AC17*$N17*$S17 -> 139836.33 | AH17: =AD17*$N17*$S17 -> 0 | AI17: =AE17*$N17*$S17 -> 0 | AJ17: =AF17*$N17*$S17 -> 0 | AK17: =($AG17*'Данные для расчета'!$B$2+'Данные для расчета'!$B$4*$AI17) -> 97885.428 | AL17: =($AG17*'Данные для расчета'!$B$3+'Данные для расчета'!$B$5*$AI17) -> 13983.633 | AM17: =AG17+AH17+AJ17+AK17+AL17 -> 251705.39 | AN17: =ROUND(AM17*'Данные для расчета'!$B$7,2) -> 55375.19 | AO17: =AM17+AN17 -> 307080.58 | AQ17: =L17*AP17 -> 0
A18: 10, 11, 41 | B18: Извещатель пожарный дымовой адресно-аналоговый | C18: ИП 212-64-R3 W1.03 | E18: Техническое обслуживание 3 Продувка от пыли | F18: 22-2203-106-3/1 | G18: Техническое обслуживание извещателя пожарного дымового оптико-электронного адресно-аналогового ИП 212-34А "ДИП-34А" - удаление пыли с поверхности дымовой камеры | H18: раз в 1 год | I18: Паспорт | J18: 1 | K18: =1818+5 -> 1823 | L18: =K18*J18 -> 1823 | M18: 1 | N18: =L18/M18 -> 1823 | O18: 311.86 | P18: 0 | Q18: 0 | R18: 5.34 | S18: 1 | T18: =O18*N18*S18 -> 568520.78 | U18: =P18*N18*S18 -> 0 | V18: =Q18*N18*S18 -> 0 | W18: =R18*N18 -> 9734.82 | X18: =($T18*'Данные для расчета'!$B$2+'Данные для расчета'!$B$4*$V18) -> 397964.55 | Y18: =($T18*'Данные для расчета'!$B$3+'Данные для расчета'!$B$5*$V18) -> 56852.078 | Z18: =T18+U18+W18+X18+Y18 -> 1033072.2 | AA18: =ROUND(Z18*'Данные для расчета'!$B$7,2) -> 227275.89 | AB18: =Z18+AA18 -> 1260348.1 | AC18: =O18/'[1]Данные для расчета'!$B$12 -> 156.08609 | AD18: =P18-Q18+AE18 -> 0 | AE18: =Q18/'[1]Данные для расчета'!$B$12 -> 0 | AF18: =R18 -> 5.34 | AG18: =AC18*$N18*$S18 -> 284544.93 | AH18: =AD18*$N18*$S18 -> 0 | AI18: =AE18*$N18*$S18 -> 0 | AJ18: =AF18*$N18*$S18 -> 9734.82 | AK18: =($AG18*'Данные для расчета'!$B$2+'Данные для расчета'!$B$4*$AI18) -> 199181.45 | AL18: =($AG18*'Данные для расчета'!$B$3+'Данные для расчета'!$B$5*$AI18) -> 28454.493 | AM18: =AG18+AH18+AJ18+AK18+AL18 -> 521915.7 | AN18: =ROUND(AM18*'Данные для расчета'!$B$7,2) -> 114821.45 | AO18: =AM18+AN18 -> 636737.15 | AQ18: =L18*AP18 -> 0
A19: 12, 40 | B19: Извещатель пожарный ручной электроконтактный адресный с встроенным изолятором короткого замыкания | C19: ИПР 513-11ИКЗ-А-R3 | E19: Контроль работоспособности извещателя | F19: 22-2203-102-1/1 | G19: ТО и регулировка извещателя пожарного ручного (Образование) | H19: раз в 6 мес. | I19: Паспорт | J19: 2 | K19: =102+1 -> 103 | L19: =K19*J19 -> 206 | M19: 1 | N19: =L19/M19 -> 206 | O19: 272.27 | P19: 0 | Q19: 0 | R19: 1.3 | S19: 1 | T19: =O19*N19*S19 -> 56087.62 | U19: =P19*N19*S19 -> 0 | V19: =Q19*N19*S19 -> 0 | W19: =R19*N19 -> 267.8 | X19: =($T19*'Данные для расчета'!$B$2+'Данные для расчета'!$B$4*$V19) -> 39261.334 | Y19: =($T19*'Данные для расчета'!$B$3+'Данные для расчета'!$B$5*$V19) -> 5608.762 | Z19: =T19+U19+W19+X19+Y19 -> 101225.52 | AA19: =ROUND(Z19*'Данные для расчета'!$B$7,2) -> 22269.61 | AB19: =Z19+AA19 -> 123495.13 | AC19: =O19/'[1]Данные для расчета'!$B$12 -> 136.27127 | AD19: =P19-Q19+AE19 -> 0 | AE19: =Q19/'[1]Данные для расчета'!$B$12 -> 0 | AF19: =R19 -> 1.3 | AG19: =AC19*$N19*$S19 -> 28071.882 | AH19: =AD19*$N19*$S19 -> 0 | AI19: =AE19*$N19*$S19 -> 0 | AJ19: =AF19*$N19*$S19 -> 267.8 | AK19: =($AG19*'Данные для расчета'!$B$2+'Данные для расчета'!$B$4*$AI19) -> 19650.317 | AL19: =($AG19*'Данные для расчета'!$B$3+'Данные для расчета'!$B$5*$AI19) -> 2807.1882 | AM19: =AG19+AH19+AJ19+AK19+AL19 -> 50797.187 | AN19: =ROUND(AM19*'Данные для расчета'!$B$7,2) -> 11175.38 | AO19: =AM19+AN19 -> 61972.567 | AP19: 0.42 | AQ19: =L19*AP19 -> 86.52
A20: 14 | B20: Извещатель пожарный тепловой | C20: ИП 101-29-PR прот. R2 | E20: Осмотр извещателя теплового | F20: 1-2201-26-1/1 | G20: Технический осмотр извещателя пожарного теплового адресно-аналогового "ATD" | H20: раз в 6 мес. | I20: Паспорт | J20: 1 | K20: 20 | L20: =K20*J20 -> 20 | M20: 1 | N20: =L20/M20 -> 20 | O20: 59.6 | P20: 5.51 | Q20: 3.32 | R20: 0 | S20: 0.75 | T20: =O20*N20*S20 -> 894 | U20: =P20*N20*S20 -> 82.65 | V20: =Q20*N20*S20 -> 49.8 | W20: =R20*N20 -> 0 | X20: =($T20*'Данные для расчета'!$B$2+'Данные для расчета'!$B$4*$V20) -> 664.644 | Y20: =($T20*'Данные для расчета'!$B$3+'Данные для расчета'!$B$5*$V20) -> 104.34 | Z20: =T20+U20+W20+X20+Y20 -> 1745.634 | AA20: =ROUND(Z20*'Данные для расчета'!$B$7,2) -> 384.04 | AB20: =Z20+AA20 -> 2129.674 | AC20: =O20/'[1]Данные для расчета'!$B$12 -> 29.82983 | AD20: =P20-Q20+AE20 -> 3.8516617 | AE20: =Q20/'[1]Данные для расчета'!$B$12 -> 1.6616617 | AF20: =R20 -> 0 | AG20: =AC20*$N20*$S20 -> 447.44745 | AH20: =AD20*$N20*$S20 -> 57.774925 | AI20: =AE20*$N20*$S20 -> 24.924925 | AJ20: =AF20*$N20*$S20 -> 0 | AK20: =($AG20*'Данные для расчета'!$B$2+'Данные для расчета'!$B$4*$AI20) -> 332.65465 | AL20: =($AG20*'Данные для расчета'!$B$3+'Данные для расчета'!$B$5*$AI20) -> 52.222222 | AM20: =AG20+AH20+AJ20+AK20+AL20 -> 890.09925 | AN20: =ROUND(AM20*'Данные для расчета'!$B$7,2) -> 195.82 | AO20: =AM20+AN20 -> 1085.9192 | AP20: 0.08 | AQ20: =L20*AP20 -> 1.6
A21: 14 | B21: Извещатель пожарный тепловой | C21: ИП 101-29-PR прот. R3 | E21: ТО извещателя пожарного теплового ИП 101-29-PR-R3 | F21: 22-2203-102-2/1 | G21: ТО и регулировка извещателя пожарного теплового (Образование) | H21: раз в 1 год | I21: Паспорт | J21: 1 | K21: 20 | L21: =K21*J21 -> 20 | M21: 1 | N21: =L21/M21 -> 20 | O21: 521.51 | P21: 0 | Q21: 0 | R21: 1.3 | S21: 1 | T21: =O21*N21*S21 -> 10430.2 | U21: =P21*N21*S21 -> 0 | V21: =Q21*N21*S21 -> 0 | W21: =R21*N21 -> 26 | X21: =($T21*'Данные для расчета'!$B$2+'Данные для расчета'!$B$4*$V21) -> 7301.14 | Y21: =($T21*'Данные для расчета'!$B$3+'Данные для расчета'!$B$5*$V21) -> 1043.02 | Z21: =T21+U21+W21+X21+Y21 -> 18800.36 | AA21: =ROUND(Z21*'Данные для расчета'!$B$7,2) -> 4136.08 | AB21: =Z21+AA21 -> 22936.44 | AC21: =O21/'[1]Данные для расчета'!$B$12 -> 261.01602 | AD21: =P21-Q21+AE21 -> 0 | AE21: =Q21/'[1]Данные для расчета'!$B$12 -> 0 | AF21: =R21 -> 1.3 | AG21: =AC21*$N21*$S21 -> 5220.3203 | AH21: =AD21*$N21*$S21 -> 0 | AI21: =AE21*$N21*$S21 -> 0 | AJ21: =AF21*$N21*$S21 -> 26 | AK21: =($AG21*'Данные для расчета'!$B$2+'Данные для расчета'!$B$4*$AI21) -> 3654.2242 | AL21: =($AG21*'Данные для расчета'!$B$3+'Данные для расчета'!$B$5*$AI21) -> 522.03203 | AM21: =AG21+AH21+AJ21+AK21+AL21 -> 9422.5766 | AN21: =ROUND(AM21*'Данные для расчета'!$B$7,2) -> 2072.97 | AO21: =AM21+AN21 -> 11495.547 | AP21: 0.7 | AQ21: =L21*AP21 -> 14
A22: 15 | B22: Извещатель пожарный дымовой линейный | C22: ИПДЛ-264/1-50 прот. R3 | E22: Проверка функционирования ИПДЛ-264/1-R3 | F22: 22-2201-82-1/1 | G22: Технический осмотр извещателя пожарного дымового линейного (ИПДЛ) | H22: раз в 6 мес. | I22: Паспорт | J22: 1 | K22: 25 | L22: =K22*J22 -> 25 | M22: 1 | N22: =L22/M22 -> 25 | O22: 125.39 | P22: 0 | Q22: 0 | R22: 0.06 | S22: 1 | T22: =O22*N22*S22 -> 3134.75 | U22: =P22*N22*S22 -> 0 | V22: =Q22*N22*S22 -> 0 | W22: =R22*N22 -> 1.5 | X22: =($T22*'Данные для расчета'!$B$2+'Данные для расчета'!$B$4*$V22) -> 2194.325 | Y22: =($T22*'Данные для расчета'!$B$3+'Данные для расчета'!$B$5*$V22) -> 313.475 | Z22: =T22+U22+W22+X22+Y22 -> 5644.05 | AA22: =ROUND(Z22*'Данные для расчета'!$B$7,2) -> 1241.69 | AB22: =Z22+AA22 -> 6885.74 | AC22: =O22/'[1]Данные для расчета'!$B$12 -> 62.757758 | AD22: =P22-Q22+AE22 -> 0 | AE22: =Q22/'[1]Данные для расчета'!$B$12 -> 0 | AF22: =R22 -> 0.06 | AG22: =AC22*$N22*$S22 -> 1568.9439 | AH22: =AD22*$N22*$S22 -> 0 | AI22: =AE22*$N22*$S22 -> 0 | AJ22: =AF22*$N22*$S22 -> 1.5 | AK22: =($AG22*'Данные для расчета'!$B$2+'Данные для расчета'!$B$4*$AI22) -> 1098.2608 | AL22: =($AG22*'Данные для расчета'!$B$3+'Данные для расчета'!$B$5*$AI22) -> 156.89439 | AM22: =AG22+AH22+AJ22+AK22+AL22 -> 2825.5991 | AN22: =ROUND(AM22*'Данные для расчета'!$B$7,2) -> 621.63 | AO22: =AM22+AN22 -> 3447.2291 | AP22: 0.18 | AQ22: =L22*AP22 -> 4.5
A23: 15 | B23: Извещатель пожарный дымовой линейный | C23: ИПДЛ-264/1-50 прот. R3 | E23: Техническое обслуживание ИПДЛ-264/1-R3 (линейный извещатель) | F23: 22-2203-127-1/1 | G23: ТО извещателя пожарного дымового линейного (ИПДЛ), до 60 м | H23: раз в год | I23: Паспорт | J23: 1 | K23: 25 | L23: =K23*J23 -> 25 | M23: 1 | N23: =L23/M23 -> 25 | O23: 334.38 | P23: 0 | Q23: 0 | R23: 67.05 | S23: 1 | T23: =O23*N23*S23 -> 8359.5 | U23: =P23*N23*S23 -> 0 | V23: =Q23*N23*S23 -> 0 | W23: =R23*N23 -> 1676.25 | X23: =($T23*'Данные для расчета'!$B$2+'Данные для расчета'!$B$4*$V23) -> 5851.65 | Y23: =($T23*'Данные для расчета'!$B$3+'Данные для расчета'!$B$5*$V23) -> 835.95 | Z23: =T23+U23+W23+X23+Y23 -> 16723.35 | AA23: =ROUND(Z23*'Данные для расчета'!$B$7,2) -> 3679.14 | AB23: =Z23+AA23 -> 20402.49 | AC23: =O23/'[1]Данные для расчета'!$B$12 -> 167.35736 | AD23: =P23-Q23+AE23 -> 0 | AE23: =Q23/'[1]Данные для расчета'!$B$12 -> 0 | AF23: =R23 -> 67.05 | AG23: =AC23*$N23*$S23 -> 4183.9339 | AH23: =AD23*$N23*$S23 -> 0 | AI23: =AE23*$N23*$S23 -> 0 | AJ23: =AF23*$N23*$S23 -> 1676.25 | AK23: =($AG23*'Данные для расчета'!$B$2+'Данные для расчета'!$B$4*$AI23) -> 2928.7538 | AL23: =($AG23*'Данные для расчета'!$B$3+'Данные для расчета'!$B$5*$AI23) -> 418.39339 | AM23: =AG23+AH23+AJ23+AK23+AL23 -> 9207.3311 | AN23: =ROUND(AM23*'Данные для расчета'!$B$7,2) -> 2025.61 | AO23: =AM23+AN23 -> 11232.941 | AP23: 0.48 | AQ23: =L23*AP23 -> 12
A24: 18, 43 | B24: Изолятор шлейфа | C24: ИЗ-1 прот. R3 | E24: Техническое обслуживание ИЗ-1 | F24: 22-2203-92-1/1 | G24: Техническое обслуживание устройства локализации коротких замыканий | H24: раз в 6 мес. | I24: Паспорт | J24: 2 | K24: =169+5 -> 174 | L24: =K24*J24 -> 348 | M24: 10 | N24: =L24/M24 -> 34.8 | O24: 250.79 | P24: 0 | Q24: 0 | R24: 3.57 | S24: 1 | T24: =O24*N24*S24 -> 8727.492 | U24: =P24*N24*S24 -> 0 | V24: =Q24*N24*S24 -> 0 | W24: =R24*N24 -> 124.236 | X24: =($T24*'Данные для расчета'!$B$2+'Данные для расчета'!$B$4*$V24) -> 6109.2444 | Y24: =($T24*'Данные для расчета'!$B$3+'Данные для расчета'!$B$5*$V24) -> 872.7492 | Z24: =T24+U24+W24+X24+Y24 -> 15833.722 | AA24: =ROUND(Z24*'Данные для расчета'!$B$7,2) -> 3483.42 | AB24: =Z24+AA24 -> 19317.142 | AC24: =O24/'[1]Данные для расчета'!$B$12 -> 125.52052 | AD24: =P24-Q24+AE24 -> 0 | AE24: =Q24/'[1]Данные для расчета'!$B$12 -> 0 | AF24: =R24 -> 3.57 | AG24: =AC24*$N24*$S24 -> 4368.1141 | AH24: =AD24*$N24*$S24 -> 0 | AI24: =AE24*$N24*$S24 -> 0 | AJ24: =AF24*$N24*$S24 -> 124.236 | AK24: =($AG24*'Данные для расчета'!$B$2+'Данные для расчета'!$B$4*$AI24) -> 3057.6799 | AL24: =($AG24*'Данные для расчета'!$B$3+'Данные для расчета'!$B$5*$AI24) -> 436.81141 | AM24: =AG24+AH24+AJ24+AK24+AL24 -> 7986.8414 | AN24: =ROUND(AM24*'Данные для расчета'!$B$7,2) -> 1757.11 | AO24: =AM24+AN24 -> 9743.9514 | AP24: 0.36 | AQ24: =L24*AP24 -> 125.28
A25: 19.36 | B25: Адресный релейный модуль | C25: РМ-1 прот. R3 | E25: ТО адресного релейного модуля | F25: 22-2203-104-4/1 | G25: Техническое обслуживание приборов системы охранно-пожарной сигнализации на базе оборудования С2000, блок сигнально-пусковой адресный С2000-СП2 - годовое | H25: раз в 6 мес. | I25: Паспорт | J25: 2 | K25: =87+14 -> 101 | L25: =K25*J25 -> 202 | M25: 1 | N25: =L25/M25 -> 202 | O25: 167.19 | P25: 0 | Q25: 0 | R25: 50.26 | S25: 1 | T25: =O25*N25*S25 -> 33772.38 | U25: =P25*N25*S25 -> 0 | V25: =Q25*N25*S25 -> 0 | W25: =R25*N25 -> 10152.52 | X25: =($T25*'Данные для расчета'!$B$2+'Данные для расчета'!$B$4*$V25) -> 23640.666 | Y25: =($T25*'Данные для расчета'!$B$3+'Данные для расчета'!$B$5*$V25) -> 3377.238 | Z25: =T25+U25+W25+X25+Y25 -> 70942.804 | AA25: =ROUND(Z25*'Данные для расчета'!$B$7,2) -> 15607.42 | AB25: =Z25+AA25 -> 86550.224 | AC25: =O25/'[1]Данные для расчета'!$B$12 -> 83.678679 | AD25: =P25-Q25+AE25 -> 0 | AE25: =Q25/'[1]Данные для расчета'!$B$12 -> 0 | AF25: =R25 -> 50.26 | AG25: =AC25*$N25*$S25 -> 16903.093 | AH25: =AD25*$N25*$S25 -> 0 | AI25: =AE25*$N25*$S25 -> 0 | AJ25: =AF25*$N25*$S25 -> 10152.52 | AK25: =($AG25*'Данные для расчета'!$B$2+'Данные для расчета'!$B$4*$AI25) -> 11832.165 | AL25: =($AG25*'Данные для расчета'!$B$3+'Данные для расчета'!$B$5*$AI25) -> 1690.3093 | AM25: =AG25+AH25+AJ25+AK25+AL25 -> 40578.088 | AN25: =ROUND(AM25*'Данные для расчета'!$B$7,2) -> 8927.18 | AO25: =AM25+AN25 -> 49505.268 | AP25: 0.24 | AQ25: =L25*AP25 -> 48.48
A26: 20 | B26: Адресный релейный модуль с контролем целостности цепи | C26: РМ‑1К‑R3 | E26: ТО адресного релейного модуля | F26: 22-2203-104-4/1 | G26: Техническое обслуживание приборов системы охранно-пожарной сигнализации на базе оборудования С2000, блок сигнально-пусковой адресный С2000-СП2 - годовое | H26: раз в 6 мес. | I26: Паспорт | J26: 2 | K26: 4 | L26: =K26*J26 -> 8 | M26: 1 | N26: =L26/M26 -> 8 | O26: 167.19 | P26: 0 | Q26: 0 | R26: 50.26 | S26: 1 | T26: =O26*N26*S26 -> 1337.52 | U26: =P26*N26*S26 -> 0 | V26: =Q26*N26*S26 -> 0 | W26: =R26*N26 -> 402.08 | X26: =($T26*'Данные для расчета'!$B$2+'Данные для расчета'!$B$4*$V26) -> 936.264 | Y26: =($T26*'Данные для расчета'!$B$3+'Данные для расчета'!$B$5*$V26) -> 133.752 | Z26: =T26+U26+W26+X26+Y26 -> 2809.616 | AA26: =ROUND(Z26*'Данные для расчета'!$B$7,2) -> 618.12 | AB26: =Z26+AA26 -> 3427.736 | AC26: =O26/'[1]Данные для расчета'!$B$12 -> 83.678679 | AD26: =P26-Q26+AE26 -> 0 | AE26: =Q26/'[1]Данные для расчета'!$B$12 -> 0 | AF26: =R26 -> 50.26 | AG26: =AC26*$N26*$S26 -> 669.42943 | AH26: =AD26*$N26*$S26 -> 0 | AI26: =AE26*$N26*$S26 -> 0 | AJ26: =AF26*$N26*$S26 -> 402.08 | AK26: =($AG26*'Данные для расчета'!$B$2+'Данные для расчета'!$B$4*$AI26) -> 468.6006 | AL26: =($AG26*'Данные для расчета'!$B$3+'Данные для расчета'!$B$5*$AI26) -> 66.942943 | AM26: =AG26+AH26+AJ26+AK26+AL26 -> 1607.053 | AN26: =ROUND(AM26*'Данные для расчета'!$B$7,2) -> 353.55 | AO26: =AM26+AN26 -> 1960.603 | AP26: 0.24 | AQ26: =L26*AP26 -> 1.92
A27: 21, 22, 40 | B27: Адресный релейный модуль | C27: РМ-4 прот. R3 | E27: ТО адресного релейного модуля | F27: 22-2203-104-11/1 | G27: Техническое обслуживание приборов системы охранно-пожарной сигнализации на базе оборудования С2000, блок сигнально-пусковой С2000-СП4 - годовое | H27: раз в 6 мес. | I27: Паспорт | J27: 2 | K27: =52+2 -> 54 | L27: =K27*J27 -> 108 | M27: 1 | N27: =L27/M27 -> 108 | O27: 181.13 | P27: 0 | Q27: 0 | R27: 66.96 | S27: 1 | T27: =O27*N27*S27 -> 19562.04 | U27: =P27*N27*S27 -> 0 | V27: =Q27*N27*S27 -> 0 | W27: =R27*N27 -> 7231.68 | X27: =($T27*'Данные для расчета'!$B$2+'Данные для расчета'!$B$4*$V27) -> 13693.428 | Y27: =($T27*'Данные для расчета'!$B$3+'Данные для расчета'!$B$5*$V27) -> 1956.204 | Z27: =T27+U27+W27+X27+Y27 -> 42443.352 | AA27: =ROUND(Z27*'Данные для расчета'!$B$7,2) -> 9337.54 | AB27: =Z27+AA27 -> 51780.892 | AC27: =O27/'[1]Данные для расчета'!$B$12 -> 90.655656 | AD27: =P27-Q27+AE27 -> 0 | AE27: =Q27/'[1]Данные для расчета'!$B$12 -> 0 | AF27: =R27 -> 66.96 | AG27: =AC27*$N27*$S27 -> 9790.8108 | AH27: =AD27*$N27*$S27 -> 0 | AI27: =AE27*$N27*$S27 -> 0 | AJ27: =AF27*$N27*$S27 -> 7231.68 | AK27: =($AG27*'Данные для расчета'!$B$2+'Данные для расчета'!$B$4*$AI27) -> 6853.5676 | AL27: =($AG27*'Данные для расчета'!$B$3+'Данные для расчета'!$B$5*$AI27) -> 979.08108 | AM27: =AG27+AH27+AJ27+AK27+AL27 -> 24855.139 | AN27: =ROUND(AM27*'Данные для расчета'!$B$7,2) -> 5468.13 | AO27: =AM27+AN27 -> 30323.269 | AP27: 0.26 | AQ27: =L27*AP27 -> 28.08
A28: 23 | B28: Адресная метка | C28: АМ-4 прот. R3 | E28: ТО адресной метки | F28: 22-2203-104-7/1 | G28: Техническое обслуживание приборов системы охранно-пожарной сигнализации на базе оборудования С2000, расширитель адресный С2000-АР2 - годовое | H28: раз в 6 мес. | I28: Паспорт | J28: 2 | K28: 4 | L28: =K28*J28 -> 8 | M28: 1 | N28: =L28/M28 -> 8 | O28: 376.19 | P28: 0 | Q28: 0 | R28: 50.14 | S28: 1 | T28: =O28*N28*S28 -> 3009.52 | U28: =P28*N28*S28 -> 0 | V28: =Q28*N28*S28 -> 0 | W28: =R28*N28 -> 401.12 | X28: =($T28*'Данные для расчета'!$B$2+'Данные для расчета'!$B$4*$V28) -> 2106.664 | Y28: =($T28*'Данные для расчета'!$B$3+'Данные для расчета'!$B$5*$V28) -> 300.952 | Z28: =T28+U28+W28+X28+Y28 -> 5818.256 | AA28: =ROUND(Z28*'Данные для расчета'!$B$7,2) -> 1280.02 | AB28: =Z28+AA28 -> 7098.276 | AC28: =O28/'[1]Данные для расчета'!$B$12 -> 188.28328 | AD28: =P28-Q28+AE28 -> 0 | AE28: =Q28/'[1]Данные для расчета'!$B$12 -> 0 | AF28: =R28 -> 50.14 | AG28: =AC28*$N28*$S28 -> 1506.2663 | AH28: =AD28*$N28*$S28 -> 0 | AI28: =AE28*$N28*$S28 -> 0 | AJ28: =AF28*$N28*$S28 -> 401.12 | AK28: =($AG28*'Данные для расчета'!$B$2+'Данные для расчета'!$B$4*$AI28) -> 1054.3864 | AL28: =($AG28*'Данные для расчета'!$B$3+'Данные для расчета'!$B$5*$AI28) -> 150.62663 | AM28: =AG28+AH28+AJ28+AK28+AL28 -> 3112.3993 | AN28: =ROUND(AM28*'Данные для расчета'!$B$7,2) -> 684.73 | AO28: =AM28+AN28 -> 3797.1293
A29: 25 | B29: Устройство коммутационное | C29: УК‑ВК/12 | E29: Техническое обслуживание устройства коммутационного 'УК-ВК' | F29: 22-2203-105-1/1 | G29: Техническое обслуживание устройства коммутационного типа 'УК-ВК' | H29: раз в 1 год | J29: 1 | K29: 10 | L29: =K29*J29 -> 10 | M29: 1 | N29: =L29/M29 -> 10 | O29: 181.13 | P29: 0 | Q29: 0 | R29: 16.73 | S29: 1 | T29: =O29*N29*S29 -> 1811.3 | U29: =P29*N29*S29 -> 0 | V29: =Q29*N29*S29 -> 0 | W29: =R29*N29 -> 167.3 | X29: =($T29*'Данные для расчета'!$B$2+'Данные для расчета'!$B$4*$V29) -> 1267.91 | Y29: =($T29*'Данные для расчета'!$B$3+'Данные для расчета'!$B$5*$V29) -> 181.13 | Z29: =T29+U29+W29+X29+Y29 -> 3427.64 | AA29: =ROUND(Z29*'Данные для расчета'!$B$7,2) -> 754.08 | AB29: =Z29+AA29 -> 4181.72 | AC29: =O29/'Данные для расчета'!$B$12 -> 90.655656 | AD29: =P29-Q29+AE29 -> 0 | AE29: =Q29/'Данные для расчета'!$B$12 -> 0 | AF29: =R29 -> 16.73 | AG29: =AC29*$N29*$S29 -> 906.55656 | AH29: =AD29*$N29*$S29 -> 0 | AI29: =AE29*$N29*$S29 -> 0 | AJ29: =AF29*$N29*$S29 -> 167.3 | AK29: =($AG29*'Данные для расчета'!$B$2+'Данные для расчета'!$B$4*$AI29) -> 634.58959 | AL29: =($AG29*'Данные для расчета'!$B$3+'Данные для расчета'!$B$5*$AI29) -> 90.655656 | AM29: =AG29+AH29+AJ29+AK29+AL29 -> 1799.1018 | AN29: =ROUND(AM29*'Данные для расчета'!$B$7,2) -> 395.8 | AO29: =AM29+AN29 -> 2194.9018 | AP29: 0.26 | AQ29: =L29*AP29 -> 2.6
A30: 28 | B30: Блок сопряжения | C30: R3‑MC1 | E30: Очистка от пыли R3-MC (модуль сопряжения) | F30: 22-2203-146-3/1 | G30: Техническое обслуживание приборов охранно пожарной сигнализации на базе оборудования С2000, преобразователь интерфейсов С2000-ПИ - ежеквартальное | H30: раз в 6 мес. | I30: Паспорт? В расценке указан период - годовое, если по правилам применения сборника - надо ставить 1 раз в год | J30: 1 | K30: 2 | L30: =K30*J30 -> 2 | M30: 1 | N30: =L30/M30 -> 2 | O30: 116.69 | P30: 0 | Q30: 0 | R30: 8.89 | S30: 1 | T30: =O30*N30*S30 -> 233.38 | U30: =P30*N30*S30 -> 0 | V30: =Q30*N30*S30 -> 0 | W30: =R30*N30 -> 17.78 | X30: =($T30*'Данные для расчета'!$B$2+'Данные для расчета'!$B$4*$V30) -> 163.366 | Y30: =($T30*'Данные для расчета'!$B$3+'Данные для расчета'!$B$5*$V30) -> 23.338 | Z30: =T30+U30+W30+X30+Y30 -> 437.864 | AA30: =ROUND(Z30*'Данные для расчета'!$B$7,2) -> 96.33 | AB30: =Z30+AA30 -> 534.194 | AC30: =O30/'Данные для расчета'!$B$12 -> 58.403403 | AD30: =P30-Q30+AE30 -> 0 | AE30: =Q30/'Данные для расчета'!$B$12 -> 0 | AF30: =R30 -> 8.89 | AG30: =AC30*$N30*$S30 -> 116.80681 | AH30: =AD30*$N30*$S30 -> 0 | AI30: =AE30*$N30*$S30 -> 0 | AJ30: =AF30*$N30*$S30 -> 17.78 | AK30: =($AG30*'Данные для расчета'!$B$2+'Данные для расчета'!$B$4*$AI30) -> 81.764765 | AL30: =($AG30*'Данные для расчета'!$B$3+'Данные для расчета'!$B$5*$AI30) -> 11.680681 | AM30: =AG30+AH30+AJ30+AK30+AL30 -> 228.03225 | AN30: =ROUND(AM30*'Данные для расчета'!$B$7,2) -> 50.17 | AO30: =AM30+AN30 -> 278.20225 | AP30: 0.18 | AQ30: =L30*AP30 -> 0.36
A31: 29 | B31: Объектовая станция | C31: РСПИ Стрелец-Мониторинг | E31: ТО объектовой станции радиосистемы передачи извещений | F31: 22-2203-119-1/1 | G31: Техническое обслуживание РСПИ "Стрелец Мониторинг", объектовая станция - ежемесячное | H31: раз в 1 мес. | I31: ПКМ | J31: 10 | K31: 1 | L31: =K31*J31 -> 10 | M31: 1 | N31: =L31/M31 -> 10 | O31: 417.99 | P31: 0 | Q31: 0 | R31: 0.44 | S31: 1 | T31: =O31*N31*S31 -> 4179.9 | U31: =P31*N31*S31 -> 0 | V31: =Q31*N31*S31 -> 0 | W31: =R31*N31 -> 4.4 | X31: =($T31*'Данные для расчета'!$B$2+'Данные для расчета'!$B$4*$V31) -> 2925.93 | Y31: =($T31*'Данные для расчета'!$B$3+'Данные для расчета'!$B$5*$V31) -> 417.99 | Z31: =T31+U31+W31+X31+Y31 -> 7528.22 | AA31: =ROUND(Z31*'Данные для расчета'!$B$7,2) -> 1656.21 | AB31: =Z31+AA31 -> 9184.43 | AC31: =O31/'[3]Данные для расчета'!$B$12 -> 209.2042 | AD31: =P31-Q31+AE31 -> 0 | AE31: =Q31/'[3]Данные для расчета'!$B$12 -> 0 | AF31: =R31 -> 0.44 | AG31: =AC31*$N31*$S31 -> 2092.042 | AH31: =AD31*$N31*$S31 -> 0 | AI31: =AE31*$N31*$S31 -> 0 | AJ31: =AF31*$N31*$S31 -> 4.4 | AK31: =($AG31*'Данные для расчета'!$B$2+'Данные для расчета'!$B$4*$AI31) -> 1464.4294 | AL31: =($AG31*'Данные для расчета'!$B$3+'Данные для расчета'!$B$5*$AI31) -> 209.2042 | AM31: =AG31+AH31+AJ31+AK31+AL31 -> 3770.0757 | AN31: =ROUND(AM31*'Данные для расчета'!$B$7,2) -> 829.42 | AO31: =AM31+AN31 -> 4599.4957 | AP31: 5.27
A32: 29 | B32: Объектовая станция | C32: РСПИ Стрелец-Мониторинг | E32: ТО объектовой станции радиосистемы передачи извещений | F32: 22-2203-119-2/1 | G32: Техническое обслуживание РСПИ "Стрелец Мониторинг", объектовая станция - полугодовое | H32: раз в 6 мес. | I32: ПКМ | J32: 2 | K32: 1 | L32: =K32*J32 -> 2 | M32: 1 | N32: =L32/M32 -> 2 | O32: 599.12 | P32: 0 | Q32: 0 | R32: 0.74 | S32: 1 | T32: =O32*N32*S32 -> 1198.24 | U32: =P32*N32*S32 -> 0 | V32: =Q32*N32*S32 -> 0 | W32: =R32*N32 -> 1.48 | X32: =($T32*'Данные для расчета'!$B$2+'Данные для расчета'!$B$4*$V32) -> 838.768 | Y32: =($T32*'Данные для расчета'!$B$3+'Данные для расчета'!$B$5*$V32) -> 119.824 | Z32: =T32+U32+W32+X32+Y32 -> 2158.312 | AA32: =ROUND(Z32*'Данные для расчета'!$B$7,2) -> 474.83 | AB32: =Z32+AA32 -> 2633.142 | AC32: =O32/'[3]Данные для расчета'!$B$12 -> 299.85986 | AD32: =P32-Q32+AE32 -> 0 | AE32: =Q32/'[3]Данные для расчета'!$B$12 -> 0 | AF32: =R32 -> 0.74 | AG32: =AC32*$N32*$S32 -> 599.71972 | AH32: =AD32*$N32*$S32 -> 0 | AI32: =AE32*$N32*$S32 -> 0 | AJ32: =AF32*$N32*$S32 -> 1.48 | AK32: =($AG32*'Данные для расчета'!$B$2+'Данные для расчета'!$B$4*$AI32) -> 419.8038 | AL32: =($AG32*'Данные для расчета'!$B$3+'Данные для расчета'!$B$5*$AI32) -> 59.971972 | AM32: =AG32+AH32+AJ32+AK32+AL32 -> 1080.9755 | AN32: =ROUND(AM32*'Данные для расчета'!$B$7,2) -> 237.81 | AO32: =AM32+AN32 -> 1318.7855 | AP32: 5.27
A33: 30 | B33: АРМ Рубеж | C33: ЦПИУ РУБЕЖ-АРМ исп.1 прот. R3 | E33: ТО рабочего места | F33: 22-2203-113-2/1 | G33: Техническое обслуживание аппаратуры программно-аппаратного комплекса "Стрелец Мониторинг", рабочее место оператора - ежемесячное | H33: раз в 1 мес. | I33: ПКМ | J33: 12 | K33: 1 | L33: =K33*J33 -> 12 | M33: 1 | N33: =L33/M33 -> 12 | O33: 264.72 | P33: 0 | Q33: 0 | R33: 0.15 | S33: 1 | T33: =O33*N33*S33 -> 3176.64 | U33: =P33*N33*S33 -> 0 | V33: =Q33*N33*S33 -> 0 | W33: =R33*N33 -> 1.8 | X33: =($T33*'Данные для расчета'!$B$2+'Данные для расчета'!$B$4*$V33) -> 2223.648 | Y33: =($T33*'Данные для расчета'!$B$3+'Данные для расчета'!$B$5*$V33) -> 317.664 | Z33: =T33+U33+W33+X33+Y33 -> 5719.752 | AA33: =ROUND(Z33*'Данные для расчета'!$B$7,2) -> 1258.35 | AB33: =Z33+AA33 -> 6978.102 | AC33: =O33/'[3]Данные для расчета'!$B$12 -> 132.49249 | AD33: =P33-Q33+AE33 -> 0 | AE33: =Q33/'[3]Данные для расчета'!$B$12 -> 0 | AF33: =R33 -> 0.15 | AG33: =AC33*$N33*$S33 -> 1589.9099 | AH33: =AD33*$N33*$S33 -> 0 | AI33: =AE33*$N33*$S33 -> 0 | AJ33: =AF33*$N33*$S33 -> 1.8 | AK33: =($AG33*'Данные для расчета'!$B$2+'Данные для расчета'!$B$4*$AI33) -> 1112.9369 | AL33: =($AG33*'Данные для расчета'!$B$3+'Данные для расчета'!$B$5*$AI33) -> 158.99099 | AM33: =AG33+AH33+AJ33+AK33+AL33 -> 2863.6378 | AN33: =ROUND(AM33*'Данные для расчета'!$B$7,2) -> 630 | AO33: =AM33+AN33 -> 3493.6378 | AP33: 0.38 | AQ33: =L33*AP33 -> 4.56
A34: 32 | B34: Источник бесперебойного питания | C34: SKAT-UPS 1500/900 | E34: Осмотр | F34: 1-2201-19-1/1 | G34: Технический осмотр Источник резервного питания "СКАТ-1200Р\20" или "СКАТ-2400Р\20" | H34: раз в 1 мес. | I34: ПКМ | J34: 10 | K34: 1 | L34: =K34*J34 -> 10 | M34: 1 | N34: =L34/M34 -> 10 | O34: 44.7 | P34: 13.78 | Q34: 8.31 | R34: 2.18 | S34: 0.75 | T34: =O34*N34*S34 -> 335.25 | U34: =P34*N34*S34 -> 103.35 | V34: =Q34*N34*S34 -> 62.325 | W34: =R34*N34 -> 21.8 | X34: =($T34*'Данные для расчета'!$B$2+'Данные для расчета'!$B$4*$V34) -> 283.2885 | Y34: =($T34*'Данные для расчета'!$B$3+'Данные для расчета'!$B$5*$V34) -> 52.2225 | Z34: =T34+U34+W34+X34+Y34 -> 795.911 | AA34: =ROUND(Z34*'Данные для расчета'!$B$7,2) -> 175.1 | AB34: =Z34+AA34 -> 971.011 | AC34: =O34/'[1]Данные для расчета'!$B$12 -> 22.372372 | AD34: =P34-Q34+AE34 -> 9.6291592 | AE34: =Q34/'[1]Данные для расчета'!$B$12 -> 4.1591592 | AF34: =R34 -> 2.18 | AG34: =AC34*$N34*$S34 -> 167.79279 | AH34: =AD34*$N34*$S34 -> 72.218694 | AI34: =AE34*$N34*$S34 -> 31.193694 | AJ34: =AF34*$N34*$S34 -> 16.35 | AK34: =($AG34*'Данные для расчета'!$B$2+'Данные для расчета'!$B$4*$AI34) -> 141.78604 | AL34: =($AG34*'Данные для расчета'!$B$3+'Данные для расчета'!$B$5*$AI34) -> 26.137387 | AM34: =AG34+AH34+AJ34+AK34+AL34 -> 424.28491 | AN34: =ROUND(AM34*'Данные для расчета'!$B$7,2) -> 93.34 | AO34: =AM34+AN34 -> 517.62491 | AQ34: =L34*AP34 -> 0
A35: 32 | B35: Источник бесперебойного питания | C35: SKAT-UPS 1500/900 | E35: Обслуживание | F35: 1-2203-20-1/1 | G35: Техническое обслуживание источника резервного питания "СКАТ-1200Р\20" или "СКАТ-2400Р\20" | H35: раз в 6 мес. | I35: ПКМ | J35: 2 | K35: 1 | L35: =K35*J35 -> 2 | M35: 1 | N35: =L35/M35 -> 2 | O35: 260.76 | P35: 55.13 | Q35: 33.23 | R35: 9.78 | S35: 0.7 | T35: =O35*N35*S35 -> 365.064 | U35: =P35*N35*S35 -> 77.182 | V35: =Q35*N35*S35 -> 46.522 | W35: =R35*N35 -> 19.56 | X35: =($T35*'Данные для расчета'!$B$2+'Данные для расчета'!$B$4*$V35) -> 291.83196 | Y35: =($T35*'Данные для расчета'!$B$3+'Данные для расчета'!$B$5*$V35) -> 50.463 | Z35: =T35+U35+W35+X35+Y35 -> 804.10096 | AA35: =ROUND(Z35*'Данные для расчета'!$B$7,2) -> 176.9 | AB35: =Z35+AA35 -> 981.00096 | AC35: =O35/'[1]Данные для расчета'!$B$12 -> 130.51051 | AD35: =P35-Q35+AE35 -> 38.531632 | AE35: =Q35/'[1]Данные для расчета'!$B$12 -> 16.631632 | AF35: =R35 -> 9.78 | AG35: =AC35*$N35*$S35 -> 182.71471 | AH35: =AD35*$N35*$S35 -> 53.944284 | AI35: =AE35*$N35*$S35 -> 23.284284 | AJ35: =AF35*$N35*$S35 -> 13.692 | AK35: =($AG35*'Данные для расчета'!$B$2+'Данные для расчета'!$B$4*$AI35) -> 146.06204 | AL35: =($AG35*'Данные для расчета'!$B$3+'Данные для расчета'!$B$5*$AI35) -> 25.256757 | AM35: =AG35+AH35+AJ35+AK35+AL35 -> 421.6698 | AN35: =ROUND(AM35*'Данные для расчета'!$B$7,2) -> 92.77 | AO35: =AM35+AN35 -> 514.4398 | AQ35: =L35*AP35 -> 0
A36: 41 | B36: Оповещатель звуковой адресный | C36: ОПОП 124-R3 | E36: Техническое обслуживание оповещателей пожарных (свет/звук/комбин.) | F36: 22-2203-74-1/1 | G36: Техническое обслуживание оповещателя пожарного звукового типа "Гамма-3" | H36: раз в 6 мес. | I36: паспорт | J36: 2 | K36: 2 | L36: =K36*J36 -> 4 | M36: 10 | N36: =L36/M36 -> 0.4 | O36: 2062.07 | P36: 0 | Q36: 0 | R36: 35.75 | S36: 1 | T36: =O36*N36*S36 -> 824.828 | U36: =P36*N36*S36 -> 0 | V36: =Q36*N36*S36 -> 0 | W36: =R36*N36 -> 14.3 | X36: =($T36*'Данные для расчета'!$B$2+'Данные для расчета'!$B$4*$V36) -> 577.3796 | Y36: =($T36*'Данные для расчета'!$B$3+'Данные для расчета'!$B$5*$V36) -> 82.4828 | Z36: =T36+U36+W36+X36+Y36 -> 1498.9904 | AA36: =ROUND(Z36*'Данные для расчета'!$B$7,2) -> 329.78 | AB36: =Z36+AA36 -> 1828.7704 | AC36: =O36/'[1]Данные для расчета'!$B$12 -> 1032.0671 | AD36: =P36-Q36+AE36 -> 0 | AE36: =Q36/'[1]Данные для расчета'!$B$12 -> 0 | AF36: =R36 -> 35.75 | AG36: =AC36*$N36*$S36 -> 412.82683 | AH36: =AD36*$N36*$S36 -> 0 | AI36: =AE36*$N36*$S36 -> 0 | AJ36: =AF36*$N36*$S36 -> 14.3 | AK36: =($AG36*'Данные для расчета'!$B$2+'Данные для расчета'!$B$4*$AI36) -> 288.97878 | AL36: =($AG36*'Данные для расчета'!$B$3+'Данные для расчета'!$B$5*$AI36) -> 41.282683 | AM36: =AG36+AH36+AJ36+AK36+AL36 -> 757.38829 | AN36: =ROUND(AM36*'Данные для расчета'!$B$7,2) -> 166.63 | AO36: =AM36+AN36 -> 924.01829 | AP36: 0.2 | AQ36: =L36*AP36 -> 0.8
A37: 42 | B37: Оповещатель световой адресный | C37: ОПОП 1-R3 | E37: Техническое обслуживание оповещателей пожарных (свет/звук/комбин.) | F37: 22-2201-80-2/1 | G37: Технический осмотр приборов системы оповещения и управления эвакуацией людей (СОУЭ), оповещатель световой - ежемесячный | H37: раз в 6 мес. | I37: паспорт | J37: 2 | K37: 2 | L37: =K37*J37 -> 4 | M37: 10 | N37: =L37/M37 -> 0.4 | O37: 633.27 | P37: 0 | Q37: 0 | R37: 1.48 | S37: 1 | T37: =O37*N37*S37 -> 253.308 | U37: =P37*N37*S37 -> 0 | V37: =Q37*N37*S37 -> 0 | W37: =R37*N37 -> 0.592 | X37: =($T37*'Данные для расчета'!$B$2+'Данные для расчета'!$B$4*$V37) -> 177.3156 | Y37: =($T37*'Данные для расчета'!$B$3+'Данные для расчета'!$B$5*$V37) -> 25.3308 | Z37: =T37+U37+W37+X37+Y37 -> 456.5464 | AA37: =ROUND(Z37*'Данные для расчета'!$B$7,2) -> 100.44 | AB37: =Z37+AA37 -> 556.9864 | AC37: =O37/'[1]Данные для расчета'!$B$12 -> 316.95195 | AD37: =P37-Q37+AE37 -> 0 | AE37: =Q37/'[1]Данные для расчета'!$B$12 -> 0 | AF37: =R37 -> 1.48 | AG37: =AC37*$N37*$S37 -> 126.78078 | AH37: =AD37*$N37*$S37 -> 0 | AI37: =AE37*$N37*$S37 -> 0 | AJ37: =AF37*$N37*$S37 -> 0.592 | AK37: =($AG37*'Данные для расчета'!$B$2+'Данные для расчета'!$B$4*$AI37) -> 88.746547 | AL37: =($AG37*'Данные для расчета'!$B$3+'Данные для расчета'!$B$5*$AI37) -> 12.678078 | AM37: =AG37+AH37+AJ37+AK37+AL37 -> 228.79741 | AN37: =ROUND(AM37*'Данные для расчета'!$B$7,2) -> 50.34 | AO37: =AM37+AN37 -> 279.13741
E38: Комплексные испытания систем пожарной сигнализации, оповещения и управления эвакуацией людей, дымоудаления | F38: 22-2203-117-1/1 | G38: Проверка работоспособности систем противопожарной защиты | H38: раз в 1 год | I38: ПКМ | J38: 1 | K38: 24508.4 | L38: =K38*J38 -> 24508.4 | M38: 1000 | N38: =L38/M38 -> 24.5084 | O38: 463.84 | P38: 0.44 | Q38: 0.01 | R38: 0 | S38: 1 | T38: =O38*N38*S38 -> 11367.976 | U38: =P38*N38*S38 -> 10.783696 | V38: =Q38*N38*S38 -> 0.245084 | W38: =R38*N38 -> 0 | X38: =($T38*'Данные для расчета'!$B$2+'Данные для расчета'!$B$4*$V38) -> 7957.7745 | Y38: =($T38*'Данные для расчета'!$B$3+'Данные для расчета'!$B$5*$V38) -> 1136.8712 | Z38: =T38+U38+W38+X38+Y38 -> 20473.406 | AA38: =ROUND(Z38*'Данные для расчета'!$B$7,2) -> 4504.15 | AB38: =Z38+AA38 -> 24977.556 | AC38: =O38/'[1]Данные для расчета'!$B$12 -> 232.15215 | AD38: =P38-Q38+AE38 -> 0.43500501 | AE38: =Q38/'[1]Данные для расчета'!$B$12 -> 0.005005005 | AF38: =R38 -> 0 | AG38: =AC38*$N38*$S38 -> 5689.6778 | AH38: =AD38*$N38*$S38 -> 10.661277 | AI38: =AE38*$N38*$S38 -> 0.12266466 | AJ38: =AF38*$N38*$S38 -> 0 | AK38: =($AG38*'Данные для расчета'!$B$2+'Данные для расчета'!$B$4*$AI38) -> 3982.8701 | AL38: =($AG38*'Данные для расчета'!$B$3+'Данные для расчета'!$B$5*$AI38) -> 569.00458 | AM38: =AG38+AH38+AJ38+AK38+AL38 -> 10252.214 | AN38: =ROUND(AM38*'Данные для расчета'!$B$7,2) -> 2255.49 | AO38: =AM38+AN38 -> 12507.704 | AP38: 0.48 | AQ38: =L38*AP38 -> 11764.032
E39: ИТОГО АПС | T39: =SUM(T3:T38) -> 1340642.4 | U39: =SUM(U3:U38) -> 7807.5132 | W39: =SUM(W3:W38) -> 31046.694 | X39: =SUM(X3:X38) -> 942114.22 | Y39: =SUM(Y3:Y38) -> 135473.69 | Z39: =SUM(Z3:Z38) -> 2457084.5 | AA39: =SUM(AA3:AA38) -> 540558.62 | AB39: =SUM(AB3:AB38) -> 2997643.1 | AG39: =SUM(AG3:AG38) -> 670992.18 | AH39: =SUM(AH3:AH38) -> 5460.7836 | AJ39: =SUM(AJ3:AJ38) -> 31035.376 | AK39: =SUM(AK3:AK38) -> 471528.64 | AL39: =SUM(AL3:AL38) -> 67804.647 | AM39: =SUM(AM3:AM38) -> 1246821.6 | AN39: =SUM(AN3:AN38) -> 274300.76 | AO39: =SUM(AO3:AO38) -> 1521122.4 | AQ39: =SUM(AQ3:AQ38) -> 12666.382
